Workbook
Name ListeComptes: 'Paramètres'!$D$10:$D$49
Name ListeTypes: 'Paramètres'!$M$10:$M$129
Name ListeMoisPaie: 'Référentiel'!$B$2:$B$121
Name ListeNatures: 'Référentiel'!$M$2:$M$26
Name ListeMois: 'Référentiel'!$A$2:$A$61
Name FinReleve: 'Paramètres'!$B$12
Name CompteSorties: 'Paramètres'!$B$13

Sheet Lisez-moi
A1: Budget — modèle de fichier source
A3: Ce classeur est un EXEMPLE complet, rempli avec des données inventées. Remplacez-les par les vôtres.
A5: À remplir : les cellules jaune pâle, sous les en-têtes bleu nuit.
A6: Calculé : les cellules grises, sous les en-têtes gris. N'écrivez rien dedans.
A8: Par où commencer
A9: 1. Paramètres : vos comptes, vos types, vos catégories, vos dates de relevé.
A10: Chaque tableau a son encadré « comment remplir », juste au-dessus.
A11: 2. Transactions : un mouvement par ligne, colonnes A à J. Les listes proposent vos comptes et vos types.
A12: 3. Paie (facultative) : un bulletin par mois.
A13: 4. Patrimoine (facultative) : le solde de chaque compte, un relevé par mois.
A14: 5. Visualisation : choisissez un mois en B1. Tout suit vos Paramètres.
A15: Soldes et recettes à gauche ; épargne et rapprochement bancaire au milieu ; dépenses par catégorie à droite.
... A40: 3. Une feuille dont le nom n'est pas reconnu est ignorée — celle-ci, par exemple.

Sheet Transactions
A1: Date | B1: Libellé | C1: Compte | D1: Type | E1: Montant brut | F1: Sens (si différent) | G1: Enseigne | H1: Événement | I1: Ville | J1: Prévisionnel | K1: Montant | L1: Sens | M1: Classe | N1: Catégorie | O1: Compté | P1: Remboursement | Q1: Dépense nette | R1: Effet sur le compte | S1: Compte lié | T1: Effet sur le compte lié | U1: Sortie d'épargne | V1: N° dépense du mois | X1: Légende : | Y1: À remplir | Z1: Calculé — n'écrivez rien
A2: 45536 | B2: Loisirs | C2: Banque A - Part commune | D2: Loisirs | E2: 91.62 | G2: Abonnement vidéo | H2: Rentrée | I2: Villebourg | K2: =IF($E2="","",ROUND($E2*IF(ISNA(MATCH($C2,'Paramètres'!$D:$D,0)),1,IF(INDEX('Paramètres'!$J:$J,MATCH($C2,'Paramètres'!$D:$D,0))="",1,INDEX('Paramètres'!$J:$J,MATCH($C2,'Paramètres'!$D:$D,0)))),2)) -> 45.81 | L2: =IF($D2="","",IF($F2<>"",$F2,IF(ISNA(MATCH($D2,'Paramètres'!$M:$M,0)),"⚠ Type inconnu",IFERROR(INDEX('Paramètres'!$P:$P,MATCH($D2,'Paramètres'!$M:$M,0))&"","")))) -> Débit | M2: =IF($D2="","",IF(ISNA(MATCH($D2,'Paramètres'!$M:$M,0)),"⚠ Type inconnu",IF($L2="Crédit","",IFERROR(INDEX('Paramètres'!$O:$O,MATCH($D2,'Paramètres'!$M:$M,0))&"","")))) -> Dépense Occasionnelle | N2: =IF($D2="","",IFERROR(INDEX('Paramètres'!$Q:$Q,MATCH($D2,'Paramètres'!$M:$M,0))&"","")) -> Loisir | O2: =IF($A2="","",IF(OR($J2<>"x",$A2<=FinReleve),1,0)) -> 1 | P2: =IF($D2="","",IF(AND($L2="Crédit",OR(IFERROR(INDEX('Paramètres'!$O:$O,MATCH($D2,'Paramètres'!$M:$M,0))&"","")<>"",ISNUMBER(SEARCH("remboursement",IFERROR(INDEX('Paramètres'!$N:$N,MATCH($D2,'Paramètres'!$M:$M,0))&"",""))))),1,0)) -> 0 | Q2: =IF($K2="","",IF(ISNUMBER(SEARCH("transfert-interne",IFERROR(INDEX('Paramètres'!$N:$N,MATCH($D2,'Paramètres'!$M:$M,0))&"",""))),0,IF($L2="Débit",$K2,IF($P2=1,-$K2,0)))) -> 45.81 | R2: =IF($K2="","",IF($L2="Crédit",$K2,-$K2)) -> -45.81 | S2: =IF($C2="","",IFERROR(INDEX('Paramètres'!$H:$H,MATCH($C2,'Paramètres'!$D:$D,0))&"","")) -> Banque A - Courant | T2: =IF($K2="","",IF($S2="",0,IF(ISNUMBER(SEARCH("apport-exterieur",IFERROR(INDEX('Paramètres'!$N:$N,MATCH($D2,'Paramètres'!$M:$M,0))&"",""))),0,IF(OR(IFERROR(INDEX('Paramètres'!$I:$I,MATCH($C2,'Paramètres'!$D:$D,0))&"","")="Les deux",IFERROR(INDEX('Paramètres'!$I:$I,MATCH($C2,'Paramètres'!$D:$D,0))&"","")=IF($P2=1,"Débit",$L2)),-IF($P2=1,-$K2,$K2),0)))) -> -45.81 | U2: =IF($K2="","",IF(ISNUMBER(SEARCH("sortie-epargne",IFERROR(INDEX('Paramètres'!$N:$N,MATCH($D2,'Paramètres'!$M:$M,0))&"",""))),$K2,0)) -> 0 | V2: =IF(AND($A2<>"",$O2=1,$L2="Débit",N($Q2)>0,$A2>=Visualisation!$B$1,$A2<Visualisation!$D$1),MAX($V$1:V1)+1,"")
A3: 45537 | B3: Alimentation compte joint | C3: Banque C - Compte joint | D3: Transfert Banque A vers Banque C | E3: 1160 | K3: =IF($E3="","",ROUND($E3*IF(ISNA(MATCH($C3,'Paramètres'!$D:$D,0)),1,IF(INDEX('Paramètres'!$J:$J,MATCH($C3,'Paramètres'!$D:$D,0))="",1,INDEX('Paramètres'!$J:$J,MATCH($C3,'Paramètres'!$D:$D,0)))),2)) -> 1160 | L3: =IF($D3="","",IF($F3<>"",$F3,IF(ISNA(MATCH($D3,'Paramètres'!$M:$M,0)),"⚠ Type inconnu",IFERROR(INDEX('Paramètres'!$P:$P,MATCH($D3,'Paramètres'!$M:$M,0))&"","")))) -> Crédit | M3: =IF($D3="","",IF(ISNA(MATCH($D3,'Paramètres'!$M:$M,0)),"⚠ Type inconnu",IF($L3="Crédit","",IFERROR(INDEX('Paramètres'!$O:$O,MATCH($D3,'Paramètres'!$M:$M,0))&"","")))) | N3: =IF($D3="","",IFERROR(INDEX('Paramètres'!$Q:$Q,MATCH($D3,'Paramètres'!$M:$M,0))&"","")) -> Comptes Bancaires | O3: =IF($A3="","",IF(OR($J3<>"x",$A3<=FinReleve),1,0)) -> 1 | P3: =IF($D3="","",IF(AND($L3="Crédit",OR(IFERROR(INDEX('Paramètres'!$O:$O,MATCH($D3,'Paramètres'!$M:$M,0))&"","")<>"",ISNUMBER(SEARCH("remboursement",IFERROR(INDEX('Paramètres'!$N:$N,MATCH($D3,'Paramètres'!$M:$M,0))&"",""))))),1,0)) -> 0 | Q3: =IF($K3="","",IF(ISNUMBER(SEARCH("transfert-interne",IFERROR(INDEX('Paramètres'!$N:$N,MATCH($D3,'Paramètres'!$M:$M,0))&"",""))),0,IF($L3="Débit",$K3,IF($P3=1,-$K3,0)))) -> 0 | R3: =IF($K3="","",IF($L3="Crédit",$K3,-$K3)) -> 1160 | S3: =IF($C3="","",IFERROR(INDEX('Paramètres'!$H:$H,MATCH($C3,'Paramètres'!$D:$D,0))&"","")) -> Banque A - Courant | T3: =IF($K3="","",IF($S3="",0,IF(ISNUMBER(SEARCH("apport-exterieur",IFERROR(INDEX('Paramètres'!$N:$N,MATCH($D3,'Paramètres'!$M:$M,0))&"",""))),0,IF(OR(IFERROR(INDEX('Paramètres'!$I:$I,MATCH($C3,'Paramètres'!$D:$D,0))&"","")="Les deux",IFERROR(INDEX('Paramètres'!$I:$I,MATCH($C3,'Paramètres'!$D:$D,0))&"","")=IF($P3=1,"Débit",$L3)),-IF($P3=1,-$K3,$K3),0)))) -> -1160 | U3: =IF($K3="","",IF(ISNUMBER(SEARCH("sortie-epargne",IFERROR(INDEX('Paramètres'!$N:$N,MATCH($D3,'Paramètres'!$M:$M,0))&"",""))),$K3,0)) -> 0 | V3: =IF(AND($A3<>"",$O3=1,$L3="Débit",N($Q3)>0,$A3>=Visualisation!$B$1,$A3<Visualisation!$D$1),MAX($V$1:V2)+1,"")
A4: 45537 | B4: Alimentation compte joint | C4: Banque B - Compte joint | D4: Transfert Banque A vers Banque B | E4: 600 | K4: =IF($E4="","",ROUND($E4*IF(ISNA(MATCH($C4,'Paramètres'!$D:$D,0)),1,IF(INDEX('Paramètres'!$J:$J,MATCH($C4,'Paramètres'!$D:$D,0))="",1,INDEX('Paramètres'!$J:$J,MATCH($C4,'Paramètres'!$D:$D,0)))),2)) -> 300 | L4: =IF($D4="","",IF($F4<>"",$F4,IF(ISNA(MATCH($D4,'Paramètres'!$M:$M,0)),"⚠ Type inconnu",IFERROR(INDEX('Paramètres'!$P:$P,MATCH($D4,'Paramètres'!$M:$M,0))&"","")))) -> Crédit | M4: =IF($D4="","",IF(ISNA(MATCH($D4,'Paramètres'!$M:$M,0)),"⚠ Type inconnu",IF($L4="Crédit","",IFERROR(INDEX('Paramètres'!$O:$O,MATCH($D4,'Paramètres'!$M:$M,0))&"","")))) | N4: =IF($D4="","",IFERROR(INDEX('Paramètres'!$Q:$Q,MATCH($D4,'Paramètres'!$M:$M,0))&"","")) -> Comptes Bancaires | O4: =IF($A4="","",IF(OR($J4<>"x",$A4<=FinReleve),1,0)) -> 1 | P4: =IF($D4="","",IF(AND($L4="Crédit",OR(IFERROR(INDEX('Paramètres'!$O:$O,MATCH($D4,'Paramètres'!$M:$M,0))&"","")<>"",ISNUMBER(SEARCH("remboursement",IFERROR(INDEX('Paramètres'!$N:$N,MATCH($D4,'Paramètres'!$M:$M,0))&"",""))))),1,0)) -> 0 | Q4: =IF($K4="","",IF(ISNUMBER(SEARCH("transfert-interne",IFERROR(INDEX('Paramètres'!$N:$N,MATCH($D4,'Paramètres'!$M:$M,0))&"",""))),0,IF($L4="Débit",$K4,IF($P4=1,-$K4,0)))) -> 0 | R4: =IF($K4="","",IF($L4="Crédit",$K4,-$K4)) -> 300 | S4: =IF($C4="","",IFERROR(INDEX('Paramètres'!$H:$H,MATCH($C4,'Paramètres'!$D:$D,0))&"","")) -> Banque A - Courant | T4: =IF($K4="","",IF($S4="",0,IF(ISNUMBER(SEARCH("apport-exterieur",IFERROR(INDEX('Paramètres'!$N:$N,MATCH($D4,'Paramètres'!$M:$M,0))&"",""))),0,IF(OR(IFERROR(INDEX('Paramètres'!$I:$I,MATCH($C4,'Paramètres'!$D:$D,0))&"","")="Les deux",IFERROR(INDEX('Paramètres'!$I:$I,MATCH($C4,'Paramètres'!$D:$D,0))&"","")=IF($P4=1,"Débit",$L4)),-IF($P4=1,-$K4,$K4),0)))) -> -300 | U4: =IF($K4="","",IF(ISNUMBER(SEARCH("sortie-epargne",IFERROR(INDEX('Paramètres'!$N:$N,MATCH($D4,'Paramètres'!$M:$M,0))&"",""))),$K4,0)) -> 0 | V4: =IF(AND($A4<>"",$O4=1,$L4="Débit",N($Q4)>0,$A4>=Visualisation!$B$1,$A4<Visualisation!$D$1),MAX($V$1:V3)+1,"")
A5: 45537 | B5: Titre restaurant | C5: Titres-restaurant | D5: cantine | E5: 8.03 | G5: Cantine | I5: Rocheville | K5: =IF($E5="","",ROUND($E5*IF(ISNA(MATCH($C5,'Paramètres'!$D:$D,0)),1,IF(INDEX('Paramètres'!$J:$J,MATCH($C5,'Paramètres'!$D:$D,0))="",1,INDEX('Paramètres'!$J:$J,MATCH($C5,'Paramètres'!$D:$D,0)))),2)) -> 8.03 | L5: =IF($D5="","",IF($F5<>"",$F5,IF(ISNA(MATCH($D5,'Paramètres'!$M:$M,0)),"⚠ Type inconnu",IFERROR(INDEX('Paramètres'!$P:$P,MATCH($D5,'Paramètres'!$M:$M,0))&"","")))) -> Débit | M5: =IF($D5="","",IF(ISNA(MATCH($D5,'Paramètres'!$M:$M,0)),"⚠ Type inconnu",IF($L5="Crédit","",IFERROR(INDEX('Paramètres'!$O:$O,MATCH($D5,'Paramètres'!$M:$M,0))&"","")))) -> Dépense Courante | N5: =IF($D5="","",IFERROR(INDEX('Paramètres'!$Q:$Q,MATCH($D5,'Paramètres'!$M:$M,0))&"","")) -> Alimentation | O5: =IF($A5="","",IF(OR($J5<>"x",$A5<=FinReleve),1,0)) -> 1 | P5: =IF($D5="","",IF(AND($L5="Crédit",OR(IFERROR(INDEX('Paramètres'!$O:$O,MATCH($D5,'Paramètres'!$M:$M,0))&"","")<>"",ISNUMBER(SEARCH("remboursement",IFERROR(INDEX('Paramètres'!$N:$N,MATCH($D5,'Paramètres'!$M:$M,0))&"",""))))),1,0)) -> 0 | Q5: =IF($K5="","",IF(ISNUMBER(SEARCH("transfert-interne",IFERROR(INDEX('Paramètres'!$N:$N,MATCH($D5,'Paramètres'!$M:$M,0))&"",""))),0,IF($L5="Débit",$K5,IF($P5=1,-$K5,0)))) -> 8.03 | R5: =IF($K5="","",IF($L5="Crédit",$K5,-$K5)) -> -8.03 | S5: =IF($C5="","",IFERROR(INDEX('Paramètres'!$H:$H,MATCH($C5,'Paramètres'!$D:$D,0))&"","")) | T5: =IF($K5="","",IF($S5="",0,IF(ISNUMBER(SEARCH("apport-exterieur",IFERROR(INDEX('Paramètres'!$N:$N,MATCH($D5,'Paramètres'!$M:$M,0))&"",""))),0,IF(OR(IFERROR(INDEX('Paramètres'!$I:$I,MATCH($C5,'Paramètres'!$D:$D,0))&"","")="Les deux",IFERROR(INDEX('Paramètres'!$I:$I,MATCH($C5,'Paramètres'!$D:$D,0))&"","")=IF($P5=1,"Débit",$L5)),-IF($P5=1,-$K5,$K5),0)))) -> 0 | U5: =IF($K5="","",IF(ISNUMBER(SEARCH("sortie-epargne",IFERROR(INDEX('Paramètres'!$N:$N,MATCH($D5,'Paramètres'!$M:$M,0))&"",""))),$K5,0)) -> 0 | V5: =IF(AND($A5<>"",$O5=1,$L5="Débit",N($Q5)>0,$A5>=Visualisation!$B$1,$A5<Visualisation!$D$1),MAX($V$1:V4)+1,"")
A6: 45538 | B6: Abonnement transport | C6: Banque A - Courant | D6: Abonnement transport | E6: 88.8 | K6: =IF($E6="","",ROUND($E6*IF(ISNA(MATCH($C6,'Paramètres'!$D:$D,0)),1,IF(INDEX('Paramètres'!$J:$J,MATCH($C6,'Paramètres'!$D:$D,0))="",1,INDEX('Paramètres'!$J:$J,MATCH($C6,'Paramètres'!$D:$D,0)))),2)) -> 88.8 | L6: =IF($D6="","",IF($F6<>"",$F6,IF(ISNA(MATCH($D6,'Paramètres'!$M:$M,0)),"⚠ Type inconnu",IFERROR(INDEX('Paramètres'!$P:$P,MATCH($D6,'Paramètres'!$M:$M,0))&"","")))) -> Débit | M6: =IF($D6="","",IF(ISNA(MATCH($D6,'Paramètres'!$M:$M,0)),"⚠ Type inconnu",IF($L6="Crédit","",IFERROR(INDEX('Paramètres'!$O:$O,MATCH($D6,'Paramètres'!$M:$M,0))&"","")))) -> Dépense Fixe | N6: =IF($D6="","",IFERROR(INDEX('Paramètres'!$Q:$Q,MATCH($D6,'Paramètres'!$M:$M,0))&"","")) -> Transport | O6: =IF($A6="","",IF(OR($J6<>"x",$A6<=FinReleve),1,0)) -> 1 | P6: =IF($D6="","",IF(AND($L6="Crédit",OR(IFERROR(INDEX('Paramètres'!$O:$O,MATCH($D6,'Paramètres'!$M:$M,0))&"","")<>"",ISNUMBER(SEARCH("remboursement",IFERROR(INDEX('Paramètres'!$N:$N,MATCH($D6,'Paramètres'!$M:$M,0))&"",""))))),1,0)) -> 0 | Q6: =IF($K6="","",IF(ISNUMBER(SEARCH("transfert-interne",IFERROR(INDEX('Paramètres'!$N:$N,MATCH($D6,'Paramètres'!$M:$M,0))&"",""))),0,IF($L6="Débit",$K6,IF($P6=1,-$K6,0)))) -> 88.8 | R6: =IF($K6="","",IF($L6="Crédit",$K6,-$K6)) -> -88.8 | S6: =IF($C6="","",IFERROR(INDEX('Paramètres'!$H:$H,MATCH($C6,'Paramètres'!$D:$D,0))&"","")) | T6: =IF($K6="","",IF($S6="",0,IF(ISNUMBER(SEARCH("apport-exterieur",IFERROR(INDEX('Paramètres'!$N:$N,MATCH($D6,'Paramètres'!$M:$M,0))&"",""))),0,IF(OR(IFERROR(INDEX('Paramètres'!$I:$I,MATCH($C6,'Paramètres'!$D:$D,0))&"","")="Les deux",IFERROR(INDEX('Paramètres'!$I:$I,MATCH($C6,'Paramètres'!$D:$D,0))&"","")=IF($P6=1,"Débit",$L6)),-IF($P6=1,-$K6,$K6),0)))) -> 0 | U6: =IF($K6="","",IF(ISNUMBER(SEARCH("sortie-epargne",IFERROR(INDEX('Paramètres'!$N:$N,MATCH($D6,'Paramètres'!$M:$M,0))&"",""))),$K6,0)) -> 0 | V6: =IF(AND($A6<>"",$O6=1,$L6="Débit",N($Q6)>0,$A6>=Visualisation!$B$1,$A6<Visualisation!$D$1),MAX($V$1:V5)+1,"")
A7: 45539 | B7: Achat carte | C7: Banque A - Part commune | D7: courses | E7: 30.86 | G7: Supermarché Centre | I7: Villebourg-sur-Rive | K7: =IF($E7="","",ROUND($E7*IF(ISNA(MATCH($C7,'Paramètres'!$D:$D,0)),1,IF(INDEX('Paramètres'!$J:$J,MATCH($C7,'Paramètres'!$D:$D,0))="",1,INDEX('Paramètres'!$J:$J,MATCH($C7,'Paramètres'!$D:$D,0)))),2)) -> 15.43 | L7: =IF($D7="","",IF($F7<>"",$F7,IF(ISNA(MATCH($D7,'Paramètres'!$M:$M,0)),"⚠ Type inconnu",IFERROR(INDEX('Paramètres'!$P:$P,MATCH($D7,'Paramètres'!$M:$M,0))&"","")))) -> Débit | M7: =IF($D7="","",IF(ISNA(MATCH($D7,'Paramètres'!$M:$M,0)),"⚠ Type inconnu",IF($L7="Crédit","",IFERROR(INDEX('Paramètres'!$O:$O,MATCH($D7,'Paramètres'!$M:$M,0))&"","")))) -> Dépense Courante | N7: =IF($D7="","",IFERROR(INDEX('Paramètres'!$Q:$Q,MATCH($D7,'Paramètres'!$M:$M,0))&"","")) -> Alimentation | O7: =IF($A7="","",IF(OR($J7<>"x",$A7<=FinReleve),1,0)) -> 1 | P7: =IF($D7="","",IF(AND($L7="Crédit",OR(IFERROR(INDEX('Paramètres'!$O:$O,MATCH($D7,'Paramètres'!$M:$M,0))&"","")<>"",ISNUMBER(SEARCH("remboursement",IFERROR(INDEX('Paramètres'!$N:$N,MATCH($D7,'Paramètres'!$M:$M,0))&"",""))))),1,0)) -> 0 | Q7: =IF($K7="","",IF(ISNUMBER(SEARCH("transfert-interne",IFERROR(INDEX('Paramètres'!$N:$N,MATCH($D7,'Paramètres'!$M:$M,0))&"",""))),0,IF($L7="Débit",$K7,IF($P7=1,-$K7,0)))) -> 15.43 | R7: =IF($K7="","",IF($L7="Crédit",$K7,-$K7)) -> -15.43 | S7: =IF($C7="","",IFERROR(INDEX('Paramètres'!$H:$H,MATCH($C7,'Paramètres'!$D:$D,0))&"","")) -> Banque A - Courant | T7: =IF($K7="","",IF($S7="",0,IF(ISNUMBER(SEARCH("apport-exterieur",IFERROR(INDEX('Paramètres'!$N:$N,MATCH($D7,'Paramètres'!$M:$M,0))&"",""))),0,IF(OR(IFERROR(INDEX('Paramètres'!$I:$I,MATCH($C7,'Paramètres'!$D:$D,0))&"","")="Les deux",IFERROR(INDEX('Paramètres'!$I:$I,MATCH($C7,'Paramètres'!$D:$D,0))&"","")=IF($P7=1,"Débit",$L7)),-IF($P7=1,-$K7,$K7),0)))) -> -15.43 | U7: =IF($K7="","",IF(ISNUMBER(SEARCH("sortie-epargne",IFERROR(INDEX('Paramètres'!$N:$N,MATCH($D7,'Paramètres'!$M:$M,0))&"",""))),$K7,0)) -> 0 | V7: =IF(AND($A7<>"",$O7=1,$L7="Débit",N($Q7)>0,$A7>=Visualisation!$B$1,$A7<Visualisation!$D$1),MAX($V$1:V6)+1,"")
A8: 45539 | B8: Dotation titres | C8: Titres-restaurant | D8: Ticket Restaurant | E8: 121.8 | K8: =IF($E8="","",ROUND($E8*IF(ISNA(MATCH($C8,'Paramètres'!$D:$D,0)),1,IF(INDEX('Paramètres'!$J:$J,MATCH($C8,'Paramètres'!$D:$D,0))="",1,INDEX('Paramètres'!$J:$J,MATCH($C8,'Paramètres'!$D:$D,0)))),2)) -> 121.8 | L8: =IF($D8="","",IF($F8<>"",$F8,IF(ISNA(MATCH($D8,'Paramètres'!$M:$M,0)),"⚠ Type inconnu",IFERROR(INDEX('Paramètres'!$P:$P,MATCH($D8,'Paramètres'!$M:$M,0))&"","")))) -> Crédit | M8: =IF($D8="","",IF(ISNA(MATCH($D8,'Paramètres'!$M:$M,0)),"⚠ Type inconnu",IF($L8="Crédit","",IFERROR(INDEX('Paramètres'!$O:$O,MATCH($D8,'Paramètres'!$M:$M,0))&"","")))) | N8: =IF($D8="","",IFERROR(INDEX('Paramètres'!$Q:$Q,MATCH($D8,'Paramètres'!$M:$M,0))&"","")) -> Comptes Bancaires | O8: =IF($A8="","",IF(OR($J8<>"x",$A8<=FinReleve),1,0)) -> 1 | P8: =IF($D8="","",IF(AND($L8="Crédit",OR(IFERROR(INDEX('Paramètres'!$O:$O,MATCH($D8,'Paramètres'!$M:$M,0))&"","")<>"",ISNUMBER(SEARCH("remboursement",IFERROR(INDEX('Paramètres'!$N:$N,MATCH($D8,'Paramètres'!$M:$M,0))&"",""))))),1,0)) -> 0 | Q8: =IF($K8="","",IF(ISNUMBER(SEARCH("transfert-interne",IFERROR(INDEX('Paramètres'!$N:$N,MATCH($D8,'Paramètres'!$M:$M,0))&"",""))),0,IF($L8="Débit",$K8,IF($P8=1,-$K8,0)))) -> 0 | R8: =IF($K8="","",IF($L8="Crédit",$K8,-$K8)) -> 121.8 | S8: =IF($C8="","",IFERROR(INDEX('Paramètres'!$H:$H,MATCH($C8,'Paramètres'!$D:$D,0))&"","")) | T8: =IF($K8="","",IF($S8="",0,IF(ISNUMBER(SEARCH("apport-exterieur",IFERROR(INDEX('Paramètres'!$N:$N,MATCH($D8,'Paramètres'!$M:$M,0))&"",""))),0,IF(OR(IFERROR(INDEX('Paramètres'!$I:$I,MATCH($C8,'Paramètres'!$D:$D,0))&"","")="Les deux",IFERROR(INDEX('Paramètres'!$I:$I,MATCH($C8,'Paramètres'!$D:$D,0))&"","")=IF($P8=1,"Débit",$L8)),-IF($P8=1,-$K8,$K8),0)))) -> 0 | U8: =IF($K8="","",IF(ISNUMBER(SEARCH("sortie-epargne",IFERROR(INDEX('Paramètres'!$N:$N,MATCH($D8,'Paramètres'!$M:$M,0))&"",""))),$K8,0)) -> 0 | V8: =IF(AND($A8<>"",$O8=1,$L8="Débit",N($Q8)>0,$A8>=Visualisation!$B$1,$A8<Visualisation!$D$1),MAX($V$1:V7)+1,"")
A9: 45540 | B9: Échéance prêt — capital | C9: Banque C - Compte joint | D9: Crédit Immobilier | E9: 645.51 | G9: Remboursement capital | K9: =IF($E9="","",ROUND($E9*IF(ISNA(MATCH($C9,'Paramètres'!$D:$D,0)),1,IF(INDEX('Paramètres'!$J:$J,MATCH($C9,'Paramètres'!$D:$D,0))="",1,INDEX('Paramètres'!$J:$J,MATCH($C9,'Paramètres'!$D:$D,0)))),2)) -> 645.51 | L9: =IF($D9="","",IF($F9<>"",$F9,IF(ISNA(MATCH($D9,'Paramètres'!$M:$M,0)),"⚠ Type inconnu",IFERROR(INDEX('Paramètres'!$P:$P,MATCH($D9,'Paramètres'!$M:$M,0))&"","")))) -> Débit | M9: =IF($D9="","",IF(ISNA(MATCH($D9,'Paramètres'!$M:$M,0)),"⚠ Type inconnu",IF($L9="Crédit","",IFERROR(INDEX('Paramètres'!$O:$O,MATCH($D9,'Paramètres'!$M:$M,0))&"","")))) | N9: =IF($D9="","",IFERROR(INDEX('Paramètres'!$Q:$Q,MATCH($D9,'Paramètres'!$M:$M,0))&"","")) -> Immobilier | O9: =IF($A9="","",IF(OR($J9<>"x",$A9<=FinReleve),1,0)) -> 1 | P9: =IF($D9="","",IF(AND($L9="Crédit",OR(IFERROR(INDEX('Paramètres'!$O:$O,MATCH($D9,'Paramètres'!$M:$M,0))&"","")<>"",ISNUMBER(SEARCH("remboursement",IFERROR(INDEX('Paramètres'!$N:$N,MATCH($D9,'Paramètres'!$M:$M,0))&"",""))))),1,0)) -> 0 | Q9: =IF($K9="","",IF(ISNUMBER(SEARCH("transfert-interne",IFERROR(INDEX('Paramètres'!$N:$N,MATCH($D9,'Paramètres'!$M:$M,0))&"",""))),0,IF($L9="Débit",$K9,IF($P9=1,-$K9,0)))) -> 645.51 | R9: =IF($K9="","",IF($L9="Crédit",$K9,-$K9)) -> -645.51 | S9: =IF($C9="","",IFERROR(INDEX('Paramètres'!$H:$H,MATCH($C9,'Paramètres'!$D:$D,0))&"","")) -> Banque A - Courant | T9: =IF($K9="","",IF($S9="",0,IF(ISNUMBER(SEARCH("apport-exterieur",IFERROR(INDEX('Paramètres'!$N:$N,MATCH($D9,'Paramètres'!$M:$M,0))&"",""))),0,IF(OR(IFERROR(INDEX('Paramètres'!$I:$I,MATCH($C9,'Paramètres'!$D:$D,0))&"","")="Les deux",IFERROR(INDEX('Paramètres'!$I:$I,MATCH($C9,'Paramètres'!$D:$D,0))&"","")=IF($P9=1,"Débit",$L9)),-IF($P9=1,-$K9,$K9),0)))) -> 0 | U9: =IF($K9="","",IF(ISNUMBER(SEARCH("sortie-epargne",IFERROR(INDEX('Paramètres'!$N:$N,MATCH($D9,'Paramètres'!$M:$M,0))&"",""))),$K9,0)) -> 0 | V9: =IF(AND($A9<>"",$O9=1,$L9="Débit",N($Q9)>0,$A9>=Visualisation!$B$1,$A9<Visualisation!$D$1),MAX($V$1:V8)+1,"")
A10: 45540 | B10: Échéance prêt — intérêts | C10: Banque C - Compte joint | D10: Intérêt du prêt | E10: 248.13 | G10: Intérêts | K10: =IF($E10="","",ROUND($E10*IF(ISNA(MATCH($C10,'Paramètres'!$D:$D,0)),1,IF(INDEX('Paramètres'!$J:$J,MATCH($C10,'Paramètres'!$D:$D,0))="",1,INDEX('Paramètres'!$J:$J,MATCH($C10,'Paramètres'!$D:$D,0)))),2)) -> 248.13 | L10: =IF($D10="","",IF($F10<>"",$F10,IF(ISNA(MATCH($D10,'Paramètres'!$M:$M,0)),"⚠ Type inconnu",IFERROR(INDEX('Paramètres'!$P:$P,MATCH($D10,'Paramètres'!$M:$M,0))&"","")))) -> Débit | M10: =IF($D10="","",IF(ISNA(MATCH($D10,'Paramètres'!$M:$M,0)),"⚠ Type inconnu",IF($L10="Crédit","",IFERROR(INDEX('Paramètres'!$O:$O,MATCH($D10,'Paramètres'!$M:$M,0))&"","")))) -> Dépense Fixe | N10: =IF($D10="","",IFERROR(INDEX('Paramètres'!$Q:$Q,MATCH($D10,'Paramètres'!$M:$M,0))&"","")) -> Immobilier | O10: =IF($A10="","",IF(OR($J10<>"x",$A10<=FinReleve),1,0)) -> 1 | P10: =IF($D10="","",IF(AND($L10="Crédit",OR(IFERROR(INDEX('Paramètres'!$O:$O,MATCH($D10,'Paramètres'!$M:$M,0))&"","")<>"",ISNUMBER(SEARCH("remboursement",IFERROR(INDEX('Paramètres'!$N:$N,MATCH($D10,'Paramètres'!$M:$M,0))&"",""))))),1,0)) -> 0 | Q10: =IF($K10="","",IF(ISNUMBER(SEARCH("transfert-interne",IFERROR(INDEX('Paramètres'!$N:$N,MATCH($D10,'Paramètres'!$M:$M,0))&"",""))),0,IF($L10="Débit",$K10,IF($P10=1,-$K10,0)))) -> 248.13 | R10: =IF($K10="","",IF($L10="Crédit",$K10,-$K10)) -> -248.13 | S10: =IF($C10="","",IFERROR(INDEX('Paramètres'!$H:$H,MATCH($C10,'Paramètres'!$D:$D,0))&"","")) -> Banque A - Courant | T10: =IF($K10="","",IF($S10="",0,IF(ISNUMBER(SEARCH("apport-exterieur",IFERROR(INDEX('Paramètres'!$N:$N,MATCH($D10,'Paramètres'!$M:$M,0))&"",""))),0,IF(OR(IFERROR(INDEX('Paramètres'!$I:$I,MATCH($C10,'Paramètres'!$D:$D,0))&"","")="Les deux",IFERROR(INDEX('Paramètres'!$I:$I,MATCH($C10,'Paramètres'!$D:$D,0))&"","")=IF($P10=1,"Débit",$L10)),-IF($P10=1,-$K10,$K10),0)))) -> 0 | U10: =IF($K10="","",IF(ISNUMBER(SEARCH("sortie-epargne",IFERROR(INDEX('Paramètres'!$N:$N,MATCH($D10,'Paramètres'!$M:$M,0))&"",""))),$K10,0)) -> 0 | V10: =IF(AND($A10<>"",$O10=1,$L10="Débit",N($Q10)>0,$A10>=Visualisation!$B$1,$A10<Visualisation!$D$1),MAX($V$1:V9)+1,"")
A11: 45540 | B11: Assurance prêt | C11: Banque C - Compte joint | D11: Assurance prêt | E11: 31.2 | K11: =IF($E11="","",ROUND($E11*IF(ISNA(MATCH($C11,'Paramètres'!$D:$D,0)),1,IF(INDEX('Paramètres'!$J:$J,MATCH($C11,'Paramètres'!$D:$D,0))="",1,INDEX('Paramètres'!$J:$J,MATCH($C11,'Paramètres'!$D:$D,0)))),2)) -> 31.2 | L11: =IF($D11="","",IF($F11<>"",$F11,IF(ISNA(MATCH($D11,'Paramètres'!$M:$M,0)),"⚠ Type inconnu",IFERROR(INDEX('Paramètres'!$P:$P,MATCH($D11,'Paramètres'!$M:$M,0))&"","")))) -> Débit | M11: =IF($D11="","",IF(ISNA(MATCH($D11,'Paramètres'!$M:$M,0)),"⚠ Type inconnu",IF($L11="Crédit","",IFERROR(INDEX('Paramètres'!$O:$O,MATCH($D11,'Paramètres'!$M:$M,0))&"","")))) -> Dépense Fixe | N11: =IF($D11="","",IFERROR(INDEX('Paramètres'!$Q:$Q,MATCH($D11,'Paramètres'!$M:$M,0))&"","")) -> Assurances | O11: =IF($A11="","",IF(OR($J11<>"x",$A11<=FinReleve),1,0)) -> 1 | P11: =IF($D11="","",IF(AND($L11="Crédit",OR(IFERROR(INDEX('Paramètres'!$O:$O,MATCH($D11,'Paramètres'!$M:$M,0))&"","")<>"",ISNUMBER(SEARCH("remboursement",IFERROR(INDEX('Paramètres'!$N:$N,MATCH($D11,'Paramètres'!$M:$M,0))&"",""))))),1,0)) -> 0 | Q11: =IF($K11="","",IF(ISNUMBER(SEARCH("transfert-interne",IFERROR(INDEX('Paramètres'!$N:$N,MATCH($D11,'Paramètres'!$M:$M,0))&"",""))),0,IF($L11="Débit",$K11,IF($P11=1,-$K11,0)))) -> 31.2 | R11: =IF($K11="","",IF($L11="Crédit",$K11,-$K11)) -> -31.2 | S11: =IF($C11="","",IFERROR(INDEX('Paramètres'!$H:$H,MATCH($C11,'Paramètres'!$D:$D,0))&"","")) -> Banque A - Courant | T11: =IF($K11="","",IF($S11="",0,IF(ISNUMBER(SEARCH("apport-exterieur",IFERROR(INDEX('Paramètres'!$N:$N,MATCH($D11,'Paramètres'!$M:$M,0))&"",""))),0,IF(OR(IFERROR(INDEX('Paramètres'!$I:$I,MATCH($C11,'Paramètres'!$D:$D,0))&"","")="Les deux",IFERROR(INDEX('Paramètres'!$I:$I,MATCH($C11,'Paramètres'!$D:$D,0))&"","")=IF($P11=1,"Débit",$L11)),-IF($P11=1,-$K11,$K11),0)))) -> 0 | U11: =IF($K11="","",IF(ISNUMBER(SEARCH("sortie-epargne",IFERROR(INDEX('Paramètres'!$N:$N,MATCH($D11,'Paramètres'!$M:$M,0))&"",""))),$K11,0)) -> 0 | V11: =IF(AND($A11<>"",$O11=1,$L11="Débit",N($Q11)>0,$A11>=Visualisation!$B$1,$A11<Visualisation!$D$1),MAX($V$1:V10)+1,"")
A12: 45541 | B12: Internet et Forfait téléphone | C12: Banque A - Courant | D12: Internet et Forfait téléphone | E12: 49.9 | K12: =IF($E12="","",ROUND($E12*IF(ISNA(MATCH($C12,'Paramètres'!$D:$D,0)),1,IF(INDEX('Paramètres'!$J:$J,MATCH($C12,'Paramètres'!$D:$D,0))="",1,INDEX('Paramètres'!$J:$J,MATCH($C12,'Paramètres'!$D:$D,0)))),2)) -> 49.9 | L12: =IF($D12="","",IF($F12<>"",$F12,IF(ISNA(MATCH($D12,'Paramètres'!$M:$M,0)),"⚠ Type inconnu",IFERROR(INDEX('Paramètres'!$P:$P,MATCH($D12,'Paramètres'!$M:$M,0))&"","")))) -> Débit | M12: =IF($D12="","",IF(ISNA(MATCH($D12,'Paramètres'!$M:$M,0)),"⚠ Type inconnu",IF($L12="Crédit","",IFERROR(INDEX('Paramètres'!$O:$O,MATCH($D12,'Paramètres'!$M:$M,0))&"","")))) -> Dépense Fixe | N12: =IF($D12="","",IFERROR(INDEX('Paramètres'!$Q:$Q,MATCH($D12,'Paramètres'!$M:$M,0))&"","")) -> Autre | O12: =IF($A12="","",IF(OR($J12<>"x",$A12<=FinReleve),1,0)) -> 1 | P12: =IF($D12="","",IF(AND($L12="Crédit",OR(IFERROR(INDEX('Paramètres'!$O:$O,MATCH($D12,'Paramètres'!$M:$M,0))&"","")<>"",ISNUMBER(SEARCH("remboursement",IFERROR(INDEX('Paramètres'!$N:$N,MATCH($D12,'Paramètres'!$M:$M,0))&"",""))))),1,0)) -> 0 | Q12: =IF($K12="","",IF(ISNUMBER(SEARCH("transfert-interne",IFERROR(INDEX('Paramètres'!$N:$N,MATCH($D12,'Paramètres'!$M:$M,0))&"",""))),0,IF($L12="Débit",$K12,IF($P12=1,-$K12,0)))) -> 49.9 | R12: =IF($K12="","",IF($L12="Crédit",$K12,-$K12)) -> -49.9 | S12: =IF($C12="","",IFERROR(INDEX('Paramètres'!$H:$H,MATCH($C12,'Paramètres'!$D:$D,0))&"","")) | T12: =IF($K12="","",IF($S12="",0,IF(ISNUMBER(SEARCH("apport-exterieur",IFERROR(INDEX('Paramètres'!$N:$N,MATCH($D12,'Paramètres'!$M:$M,0))&"",""))),0,IF(OR(IFERROR(INDEX('Paramètres'!$I:$I,MATCH($C12,'Paramètres'!$D:$D,0))&"","")="Les deux",IFERROR(INDEX('Paramètres'!$I:$I,MATCH($C12,'Paramètres'!$D:$D,0))&"","")=IF($P12=1,"Débit",$L12)),-IF($P12=1,-$K12,$K12),0)))) -> 0 | U12: =IF($K12="","",IF(ISNUMBER(SEARCH("sortie-epargne",IFERROR(INDEX('Paramètres'!$N:$N,MATCH($D12,'Paramètres'!$M:$M,0))&"",""))),$K12,0)) -> 0 | V12: =IF(AND($A12<>"",$O12=1,$L12="Débit",N($Q12)>0,$A12>=Visualisation!$B$1,$A12<Visualisation!$D$1),MAX($V$1:V11)+1,"")
A13: 45542 | B13: Carburant | C13: Banque A - Courant | D13: Essence | E13: 80.64 | G13: Parking | I13: Grandval | K13: =IF($E13="","",ROUND($E13*IF(ISNA(MATCH($C13,'Paramètres'!$D:$D,0)),1,IF(INDEX('Paramètres'!$J:$J,MATCH($C13,'Paramètres'!$D:$D,0))="",1,INDEX('Paramètres'!$J:$J,MATCH($C13,'Paramètres'!$D:$D,0)))),2)) -> 80.64 | L13: =IF($D13="","",IF($F13<>"",$F13,IF(ISNA(MATCH($D13,'Paramètres'!$M:$M,0)),"⚠ Type inconnu",IFERROR(INDEX('Paramètres'!$P:$P,MATCH($D13,'Paramètres'!$M:$M,0))&"","")))) -> Débit | M13: =IF($D13="","",IF(ISNA(MATCH($D13,'Paramètres'!$M:$M,0)),"⚠ Type inconnu",IF($L13="Crédit","",IFERROR(INDEX('Paramètres'!$O:$O,MATCH($D13,'Paramètres'!$M:$M,0))&"","")))) -> Dépense Courante | N13: =IF($D13="","",IFERROR(INDEX('Paramètres'!$Q:$Q,MATCH($D13,'Paramètres'!$M:$M,0))&"","")) -> Transport | O13: =IF($A13="","",IF(OR($J13<>"x",$A13<=FinReleve),1,0)) -> 1 | P13: =IF($D13="","",IF(AND($L13="Crédit",OR(IFERROR(INDEX('Paramètres'!$O:$O,MATCH($D13,'Paramètres'!$M:$M,0))&"","")<>"",ISNUMBER(SEARCH("remboursement",IFERROR(INDEX('Paramètres'!$N:$N,MATCH($D13,'Paramètres'!$M:$M,0))&"",""))))),1,0)) -> 0 | Q13: =IF($K13="","",IF(ISNUMBER(SEARCH("transfert-interne",IFERROR(INDEX('Paramètres'!$N:$N,MATCH($D13,'Paramètres'!$M:$M,0))&"",""))),0,IF($L13="Débit",$K13,IF($P13=1,-$K13,0)))) -> 80.64 | R13: =IF($K13="","",IF($L13="Crédit",$K13,-$K13)) -> -80.64 | S13: =IF($C13="","",IFERROR(INDEX('Paramètres'!$H:$H,MATCH($C13,'Paramètres'!$D:$D,0))&"","")) | T13: =IF($K13="","",IF($S13="",0,IF(ISNUMBER(SEARCH("apport-exterieur",IFERROR(INDEX('Paramètres'!$N:$N,MATCH($D13,'Paramètres'!$M:$M,0))&"",""))),0,IF(OR(IFERROR(INDEX('Paramètres'!$I:$I,MATCH($C13,'Paramètres'!$D:$D,0))&"","")="Les deux",IFERROR(INDEX('Paramètres'!$I:$I,MATCH($C13,'Paramètres'!$D:$D,0))&"","")=IF($P13=1,"Débit",$L13)),-IF($P13=1,-$K13,$K13),0)))) -> 0 | U13: =IF($K13="","",IF(ISNUMBER(SEARCH("sortie-epargne",IFERROR(INDEX('Paramètres'!$N:$N,MATCH($D13,'Paramètres'!$M:$M,0))&"",""))),$K13,0)) -> 0 | V13: =IF(AND($A13<>"",$O13=1,$L13="Débit",N($Q13)>0,$A13>=Visualisation!$B$1,$A13<Visualisation!$D$1),MAX($V$1:V12)+1,"")
A14: 45543 | B14: Frais de Copropriété | C14: Banque C - Compte joint | D14: Frais de Copropriété | E14: 168 | K14: =IF($E14="","",ROUND($E14*IF(ISNA(MATCH($C14,'Paramètres'!$D:$D,0)),1,IF(INDEX('Paramètres'!$J:$J,MATCH($C14,'Paramètres'!$D:$D,0))="",1,INDEX('Paramètres'!$J:$J,MATCH($C14,'Paramètres'!$D:$D,0)))),2)) -> 168 | L14: =IF($D14="","",IF($F14<>"",$F14,IF(ISNA(MATCH($D14,'Paramètres'!$M:$M,0)),"⚠ Type inconnu",IFERROR(INDEX('Paramètres'!$P:$P,MATCH($D14,'Paramètres'!$M:$M,0))&"","")))) -> Débit | M14: =IF($D14="","",IF(ISNA(MATCH($D14,'Paramètres'!$M:$M,0)),"⚠ Type inconnu",IF($L14="Crédit","",IFERROR(INDEX('Paramètres'!$O:$O,MATCH($D14,'Paramètres'!$M:$M,0))&"","")))) -> Dépense Fixe | N14: =IF($D14="","",IFERROR(INDEX('Paramètres'!$Q:$Q,MATCH($D14,'Paramètres'!$M:$M,0))&"","")) -> Immobilier | O14: =IF($A14="","",IF(OR($J14<>"x",$A14<=FinReleve),1,0)) -> 1 | P14: =IF($D14="","",IF(AND($L14="Crédit",OR(IFERROR(INDEX('Paramètres'!$O:$O,MATCH($D14,'Paramètres'!$M:$M,0))&"","")<>"",ISNUMBER(SEARCH("remboursement",IFERROR(INDEX('Paramètres'!$N:$N,MATCH($D14,'Paramètres'!$M:$M,0))&"",""))))),1,0)) -> 0 | Q14: =IF($K14="","",IF(ISNUMBER(SEARCH("transfert-interne",IFERROR(INDEX('Paramètres'!$N:$N,MATCH($D14,'Paramètres'!$M:$M,0))&"",""))),0,IF($L14="Débit",$K14,IF($P14=1,-$K14,0)))) -> 168 | R14: =IF($K14="","",IF($L14="Crédit",$K14,-$K14)) -> -168 | S14: =IF($C14="","",IFERROR(INDEX('Paramètres'!$H:$H,MATCH($C14,'Paramètres'!$D:$D,0))&"","")) -> Banque A - Courant | T14: =IF($K14="","",IF($S14="",0,IF(ISNUMBER(SEARCH("apport-exterieur",IFERROR(INDEX('Paramètres'!$N:$N,MATCH($D14,'Paramètres'!$M:$M,0))&"",""))),0,IF(OR(IFERROR(INDEX('Paramètres'!$I:$I,MATCH($C14,'Paramètres'!$D:$D,0))&"","")="Les deux",IFERROR(INDEX('Paramètres'!$I:$I,MATCH($C14,'Paramètres'!$D:$D,0))&"","")=IF($P14=1,"Débit",$L14)),-IF($P14=1,-$K14,$K14),0)))) -> 0 | U14: =IF($K14="","",IF(ISNUMBER(SEARCH("sortie-epargne",IFERROR(INDEX('Paramètres'!$N:$N,MATCH($D14,'Paramètres'!$M:$M,0))&"",""))),$K14,0)) -> 0 | V14: =IF(AND($A14<>"",$O14=1,$L14="Débit",N($Q14)>0,$A14>=Visualisation!$B$1,$A14<Visualisation!$D$1),MAX($V$1:V13)+1,"")
A15: 45543 | B15: Titre restaurant | C15: Titres-restaurant | D15: cantine | E15: 8.1 | G15: Cantine | I15: Grandval | K15: =IF($E15="","",ROUND($E15*IF(ISNA(MATCH($C15,'Paramètres'!$D:$D,0)),1,IF(INDEX('Paramètres'!$J:$J,MATCH($C15,'Paramètres'!$D:$D,0))="",1,INDEX('Paramètres'!$J:$J,MATCH($C15,'Paramètres'!$D:$D,0)))),2)) -> 8.1 | L15: =IF($D15="","",IF($F15<>"",$F15,IF(ISNA(MATCH($D15,'Paramètres'!$M:$M,0)),"⚠ Type inconnu",IFERROR(INDEX('Paramètres'!$P:$P,MATCH($D15,'Paramètres'!$M:$M,0))&"","")))) -> Débit | M15: =IF($D15="","",IF(ISNA(MATCH($D15,'Paramètres'!$M:$M,0)),"⚠ Type inconnu",IF($L15="Crédit","",IFERROR(INDEX('Paramètres'!$O:$O,MATCH($D15,'Paramètres'!$M:$M,0))&"","")))) -> Dépense Courante | N15: =IF($D15="","",IFERROR(INDEX('Paramètres'!$Q:$Q,MATCH($D15,'Paramètres'!$M:$M,0))&"","")) -> Alimentation | O15: =IF($A15="","",IF(OR($J15<>"x",$A15<=FinReleve),1,0)) -> 1 | P15: =IF($D15="","",IF(AND($L15="Crédit",OR(IFERROR(INDEX('Paramètres'!$O:$O,MATCH($D15,'Paramètres'!$M:$M,0))&"","")<>"",ISNUMBER(SEARCH("remboursement",IFERROR(INDEX('Paramètres'!$N:$N,MATCH($D15,'Paramètres'!$M:$M,0))&"",""))))),1,0)) -> 0 | Q15: =IF($K15="","",IF(ISNUMBER(SEARCH("transfert-interne",IFERROR(INDEX('Paramètres'!$N:$N,MATCH($D15,'Paramètres'!$M:$M,0))&"",""))),0,IF($L15="Débit",$K15,IF($P15=1,-$K15,0)))) -> 8.1 | R15: =IF($K15="","",IF($L15="Crédit",$K15,-$K15)) -> -8.1 | S15: =IF($C15="","",IFERROR(INDEX('Paramètres'!$H:$H,MATCH($C15,'Paramètres'!$D:$D,0))&"","")) | T15: =IF($K15="","",IF($S15="",0,IF(ISNUMBER(SEARCH("apport-exterieur",IFERROR(INDEX('Paramètres'!$N:$N,MATCH($D15,'Paramètres'!$M:$M,0))&"",""))),0,IF(OR(IFERROR(INDEX('Paramètres'!$I:$I,MATCH($C15,'Paramètres'!$D:$D,0))&"","")="Les deux",IFERROR(INDEX('Paramètres'!$I:$I,MATCH($C15,'Paramètres'!$D:$D,0))&"","")=IF($P15=1,"Débit",$L15)),-IF($P15=1,-$K15,$K15),0)))) -> 0 | U15: =IF($K15="","",IF(ISNUMBER(SEARCH("sortie-epargne",IFERROR(INDEX('Paramètres'!$N:$N,MATCH($D15,'Paramètres'!$M:$M,0))&"",""))),$K15,0)) -> 0 | V15: =IF(AND($A15<>"",$O15=1,$L15="Débit",N($Q15)>0,$A15>=Visualisation!$B$1,$A15<Visualisation!$D$1),MAX($V$1:V14)+1,"")
A16: 45544 | B16: Achat carte | C16: Banque B - Compte joint | D16: courses | E16: 145.44 | G16: Supermarché Ouest | I16: Villebourg-sur-Rive | K16: =IF($E16="","",ROUND($E16*IF(ISNA(MATCH($C16,'Paramètres'!$D:$D,0)),1,IF(INDEX('Paramètres'!$J:$J,MATCH($C16,'Paramètres'!$D:$D,0))="",1,INDEX('Paramètres'!$J:$J,MATCH($C16,'Paramètres'!$D:$D,0)))),2)) -> 72.72 | L16: =IF($D16="","",IF($F16<>"",$F16,IF(ISNA(MATCH($D16,'Paramètres'!$M:$M,0)),"⚠ Type inconnu",IFERROR(INDEX('Paramètres'!$P:$P,MATCH($D16,'Paramètres'!$M:$M,0))&"","")))) -> Débit | M16: =IF($D16="","",IF(ISNA(MATCH($D16,'Paramètres'!$M:$M,0)),"⚠ Type inconnu",IF($L16="Crédit","",IFERROR(INDEX('Paramètres'!$O:$O,MATCH($D16,'Paramètres'!$M:$M,0))&"","")))) -> Dépense Courante | N16: =IF($D16="","",IFERROR(INDEX('Paramètres'!$Q:$Q,MATCH($D16,'Paramètres'!$M:$M,0))&"","")) -> Alimentation | O16: =IF($A16="","",IF(OR($J16<>"x",$A16<=FinReleve),1,0)) -> 1 | P16: =IF($D16="","",IF(AND($L16="Crédit",OR(IFERROR(INDEX('Paramètres'!$O:$O,MATCH($D16,'Paramètres'!$M:$M,0))&"","")<>"",ISNUMBER(SEARCH("remboursement",IFERROR(INDEX('Paramètres'!$N:$N,MATCH($D16,'Paramètres'!$M:$M,0))&"",""))))),1,0)) -> 0 | Q16: =IF($K16="","",IF(ISNUMBER(SEARCH("transfert-interne",IFERROR(INDEX('Paramètres'!$N:$N,MATCH($D16,'Paramètres'!$M:$M,0))&"",""))),0,IF($L16="Débit",$K16,IF($P16=1,-$K16,0)))) -> 72.72 | R16: =IF($K16="","",IF($L16="Crédit",$K16,-$K16)) -> -72.72 | S16: =IF($C16="","",IFERROR(INDEX('Paramètres'!$H:$H,MATCH($C16,'Paramètres'!$D:$D,0))&"","")) -> Banque A - Courant | T16: =IF($K16="","",IF($S16="",0,IF(ISNUMBER(SEARCH("apport-exterieur",IFERROR(INDEX('Paramètres'!$N:$N,MATCH($D16,'Paramètres'!$M:$M,0))&"",""))),0,IF(OR(IFERROR(INDEX('Paramètres'!$I:$I,MATCH($C16,'Paramètres'!$D:$D,0))&"","")="Les deux",IFERROR(INDEX('Paramètres'!$I:$I,MATCH($C16,'Paramètres'!$D:$D,0))&"","")=IF($P16=1,"Débit",$L16)),-IF($P16=1,-$K16,$K16),0)))) -> 0 | U16: =IF($K16="","",IF(ISNUMBER(SEARCH("sortie-epargne",IFERROR(INDEX('Paramètres'!$N:$N,MATCH($D16,'Paramètres'!$M:$M,0))&"",""))),$K16,0)) -> 0 | V16: =IF(AND($A16<>"",$O16=1,$L16="Débit",N($Q16)>0,$A16>=Visualisation!$B$1,$A16<Visualisation!$D$1),MAX($V$1:V15)+1,"")
A17: 45545 | B17: Assurance habitation | C17: Banque A - Courant | D17: Assurance habitation | E17: 22.4 | K17: =IF($E17="","",ROUND($E17*IF(ISNA(MATCH($C17,'Paramètres'!$D:$D,0)),1,IF(INDEX('Paramètres'!$J:$J,MATCH($C17,'Paramètres'!$D:$D,0))="",1,INDEX('Paramètres'!$J:$J,MATCH($C17,'Paramètres'!$D:$D,0)))),2)) -> 22.4 | L17: =IF($D17="","",IF($F17<>"",$F17,IF(ISNA(MATCH($D17,'Paramètres'!$M:$M,0)),"⚠ Type inconnu",IFERROR(INDEX('Paramètres'!$P:$P,MATCH($D17,'Paramètres'!$M:$M,0))&"","")))) -> Débit | M17: =IF($D17="","",IF(ISNA(MATCH($D17,'Paramètres'!$M:$M,0)),"⚠ Type inconnu",IF($L17="Crédit","",IFERROR(INDEX('Paramètres'!$O:$O,MATCH($D17,'Paramètres'!$M:$M,0))&"","")))) -> Dépense Fixe | N17: =IF($D17="","",IFERROR(INDEX('Paramètres'!$Q:$Q,MATCH($D17,'Paramètres'!$M:$M,0))&"","")) -> Assurances | O17: =IF($A17="","",IF(OR($J17<>"x",$A17<=FinReleve),1,0)) -> 1 | P17: =IF($D17="","",IF(AND($L17="Crédit",OR(IFERROR(INDEX('Paramètres'!$O:$O,MATCH($D17,'Paramètres'!$M:$M,0))&"","")<>"",ISNUMBER(SEARCH("remboursement",IFERROR(INDEX('Paramètres'!$N:$N,MATCH($D17,'Paramètres'!$M:$M,0))&"",""))))),1,0)) -> 0 | Q17: =IF($K17="","",IF(ISNUMBER(SEARCH("transfert-interne",IFERROR(INDEX('Paramètres'!$N:$N,MATCH($D17,'Paramètres'!$M:$M,0))&"",""))),0,IF($L17="Débit",$K17,IF($P17=1,-$K17,0)))) -> 22.4 | R17: =IF($K17="","",IF($L17="Crédit",$K17,-$K17)) -> -22.4 | S17: =IF($C17="","",IFERROR(INDEX('Paramètres'!$H:$H,MATCH($C17,'Paramètres'!$D:$D,0))&"","")) | T17: =IF($K17="","",IF($S17="",0,IF(ISNUMBER(SEARCH("apport-exterieur",IFERROR(INDEX('Paramètres'!$N:$N,MATCH($D17,'Paramètres'!$M:$M,0))&"",""))),0,IF(OR(IFERROR(INDEX('Paramètres'!$I:$I,MATCH($C17,'Paramètres'!$D:$D,0))&"","")="Les deux",IFERROR(INDEX('Paramètres'!$I:$I,MATCH($C17,'Paramètres'!$D:$D,0))&"","")=IF($P17=1,"Débit",$L17)),-IF($P17=1,-$K17,$K17),0)))) -> 0 | U17: =IF($K17="","",IF(ISNUMBER(SEARCH("sortie-epargne",IFERROR(INDEX('Paramètres'!$N:$N,MATCH($D17,'Paramètres'!$M:$M,0))&"",""))),$K17,0)) -> 0 | V17: =IF(AND($A17<>"",$O17=1,$L17="Débit",N($Q17)>0,$A17>=Visualisation!$B$1,$A17<Visualisation!$D$1),MAX($V$1:V16)+1,"")
A18: 45545 | B18: Achat carte | C18: Banque B - Compte joint | D18: courses | E18: 31.26 | G18: Supermarché Ouest | I18: Villebourg | K18: =IF($E18="","",ROUND($E18*IF(ISNA(MATCH($C18,'Paramètres'!$D:$D,0)),1,IF(INDEX('Paramètres'!$J:$J,MATCH($C18,'Paramètres'!$D:$D,0))="",1,INDEX('Paramètres'!$J:$J,MATCH($C18,'Paramètres'!$D:$D,0)))),2)) -> 15.63 | L18: =IF($D18="","",IF($F18<>"",$F18,IF(ISNA(MATCH($D18,'Paramètres'!$M:$M,0)),"⚠ Type inconnu",IFERROR(INDEX('Paramètres'!$P:$P,MATCH($D18,'Paramètres'!$M:$M,0))&"","")))) -> Débit | M18: =IF($D18="","",IF(ISNA(MATCH($D18,'Paramètres'!$M:$M,0)),"⚠ Type inconnu",IF($L18="Crédit","",IFERROR(INDEX('Paramètres'!$O:$O,MATCH($D18,'Paramètres'!$M:$M,0))&"","")))) -> Dépense Courante | N18: =IF($D18="","",IFERROR(INDEX('Paramètres'!$Q:$Q,MATCH($D18,'Paramètres'!$M:$M,0))&"","")) -> Alimentation | O18: =IF($A18="","",IF(OR($J18<>"x",$A18<=FinReleve),1,0)) -> 1 | P18: =IF($D18="","",IF(AND($L18="Crédit",OR(IFERROR(INDEX('Paramètres'!$O:$O,MATCH($D18,'Paramètres'!$M:$M,0))&"","")<>"",ISNUMBER(SEARCH("remboursement",IFERROR(INDEX('Paramètres'!$N:$N,MATCH($D18,'Paramètres'!$M:$M,0))&"",""))))),1,0)) -> 0 | Q18: =IF($K18="","",IF(ISNUMBER(SEARCH("transfert-interne",IFERROR(INDEX('Paramètres'!$N:$N,MATCH($D18,'Paramètres'!$M:$M,0))&"",""))),0,IF($L18="Débit",$K18,IF($P18=1,-$K18,0)))) -> 15.63 | R18: =IF($K18="","",IF($L18="Crédit",$K18,-$K18)) -> -15.63 | S18: =IF($C18="","",IFERROR(INDEX('Paramètres'!$H:$H,MATCH($C18,'Paramètres'!$D:$D,0))&"","")) -> Banque A - Courant | T18: =IF($K18="","",IF($S18="",0,IF(ISNUMBER(SEARCH("apport-exterieur",IFERROR(INDEX('Paramètres'!$N:$N,MATCH($D18,'Paramètres'!$M:$M,0))&"",""))),0,IF(OR(IFERROR(INDEX('Paramètres'!$I:$I,MATCH($C18,'Paramètres'!$D:$D,0))&"","")="Les deux",IFERROR(INDEX('Paramètres'!$I:$I,MATCH($C18,'Paramètres'!$D:$D,0))&"","")=IF($P18=1,"Débit",$L18)),-IF($P18=1,-$K18,$K18),0)))) -> 0 | U18: =IF($K18="","",IF(ISNUMBER(SEARCH("sortie-epargne",IFERROR(INDEX('Paramètres'!$N:$N,MATCH($D18,'Paramètres'!$M:$M,0))&"",""))),$K18,0)) -> 0 | V18: =IF(AND($A18<>"",$O18=1,$L18="Débit",N($Q18)>0,$A18>=Visualisation!$B$1,$A18<Visualisation!$D$1),MAX($V$1:V17)+1,"")
A19: 45547 | B19: Assurance auto | C19: Banque A - Courant | D19: Assurance auto | E19: 47.9 | K19: =IF($E19="","",ROUND($E19*IF(ISNA(MATCH($C19,'Paramètres'!$D:$D,0)),1,IF(INDEX('Paramètres'!$J:$J,MATCH($C19,'Paramètres'!$D:$D,0))="",1,INDEX('Paramètres'!$J:$J,MATCH($C19,'Paramètres'!$D:$D,0)))),2)) -> 47.9 | L19: =IF($D19="","",IF($F19<>"",$F19,IF(ISNA(MATCH($D19,'Paramètres'!$M:$M,0)),"⚠ Type inconnu",IFERROR(INDEX('Paramètres'!$P:$P,MATCH($D19,'Paramètres'!$M:$M,0))&"","")))) -> Débit | M19: =IF($D19="","",IF(ISNA(MATCH($D19,'Paramètres'!$M:$M,0)),"⚠ Type inconnu",IF($L19="Crédit","",IFERROR(INDEX('Paramètres'!$O:$O,MATCH($D19,'Paramètres'!$M:$M,0))&"","")))) -> Dépense Fixe | N19: =IF($D19="","",IFERROR(INDEX('Paramètres'!$Q:$Q,MATCH($D19,'Paramètres'!$M:$M,0))&"","")) -> Assurances | O19: =IF($A19="","",IF(OR($J19<>"x",$A19<=FinReleve),1,0)) -> 1 | P19: =IF($D19="","",IF(AND($L19="Crédit",OR(IFERROR(INDEX('Paramètres'!$O:$O,MATCH($D19,'Paramètres'!$M:$M,0))&"","")<>"",ISNUMBER(SEARCH("remboursement",IFERROR(INDEX('Paramètres'!$N:$N,MATCH($D19,'Paramètres'!$M:$M,0))&"",""))))),1,0)) -> 0 | Q19: =IF($K19="","",IF(ISNUMBER(SEARCH("transfert-interne",IFERROR(INDEX('Paramètres'!$N:$N,MATCH($D19,'Paramètres'!$M:$M,0))&"",""))),0,IF($L19="Débit",$K19,IF($P19=1,-$K19,0)))) -> 47.9 | R19: =IF($K19="","",IF($L19="Crédit",$K19,-$K19)) -> -47.9 | S19: =IF($C19="","",IFERROR(INDEX('Paramètres'!$H:$H,MATCH($C19,'Paramètres'!$D:$D,0))&"","")) | T19: =IF($K19="","",IF($S19="",0,IF(ISNUMBER(SEARCH("apport-exterieur",IFERROR(INDEX('Paramètres'!$N:$N,MATCH($D19,'Paramètres'!$M:$M,0))&"",""))),0,IF(OR(IFERROR(INDEX('Paramètres'!$I:$I,MATCH($C19,'Paramètres'!$D:$D,0))&"","")="Les deux",IFERROR(INDEX('Paramètres'!$I:$I,MATCH($C19,'Paramètres'!$D:$D,0))&"","")=IF($P19=1,"Débit",$L19)),-IF($P19=1,-$K19,$K19),0)))) -> 0 | U19: =IF($K19="","",IF(ISNUMBER(SEARCH("sortie-epargne",IFERROR(INDEX('Paramètres'!$N:$N,MATCH($D19,'Paramètres'!$M:$M,0))&"",""))),$K19,0)) -> 0 | V19: =IF(AND($A19<>"",$O19=1,$L19="Débit",N($Q19)>0,$A19>=Visualisation!$B$1,$A19<Visualisation!$D$1),MAX($V$1:V18)+1,"")
A20: 45547 | B20: Achat carte | C20: Banque B - Compte joint | D20: courses | E20: 191.52 | G20: Primeur | I20: Grandval | K20: =IF($E20="","",ROUND($E20*IF(ISNA(MATCH($C20,'Paramètres'!$D:$D,0)),1,IF(INDEX('Paramètres'!$J:$J,MATCH($C20,'Paramètres'!$D:$D,0))="",1,INDEX('Paramètres'!$J:$J,MATCH($C20,'Paramètres'!$D:$D,0)))),2)) -> 95.76 | L20: =IF($D20="","",IF($F20<>"",$F20,IF(ISNA(MATCH($D20,'Paramètres'!$M:$M,0)),"⚠ Type inconnu",IFERROR(INDEX('Paramètres'!$P:$P,MATCH($D20,'Paramètres'!$M:$M,0))&"","")))) -> Débit | M20: =IF($D20="","",IF(ISNA(MATCH($D20,'Paramètres'!$M:$M,0)),"⚠ Type inconnu",IF($L20="Crédit","",IFERROR(INDEX('Paramètres'!$O:$O,MATCH($D20,'Paramètres'!$M:$M,0))&"","")))) -> Dépense Courante | N20: =IF($D20="","",IFERROR(INDEX('Paramètres'!$Q:$Q,MATCH($D20,'Paramètres'!$M:$M,0))&"","")) -> Alimentation | O20: =IF($A20="","",IF(OR($J20<>"x",$A20<=FinReleve),1,0)) -> 1 | P20: =IF($D20="","",IF(AND($L20="Crédit",OR(IFERROR(INDEX('Paramètres'!$O:$O,MATCH($D20,'Paramètres'!$M:$M,0))&"","")<>"",ISNUMBER(SEARCH("remboursement",IFERROR(INDEX('Paramètres'!$N:$N,MATCH($D20,'Paramètres'!$M:$M,0))&"",""))))),1,0)) -> 0 | Q20: =IF($K20="","",IF(ISNUMBER(SEARCH("transfert-interne",IFERROR(INDEX('Paramètres'!$N:$N,MATCH($D20,'Paramètres'!$M:$M,0))&"",""))),0,IF($L20="Débit",$K20,IF($P20=1,-$K20,0)))) -> 95.76 | R20: =IF($K20="","",IF($L20="Crédit",$K20,-$K20)) -> -95.76 | S20: =IF($C20="","",IFERROR(INDEX('Paramètres'!$H:$H,MATCH($C20,'Paramètres'!$D:$D,0))&"","")) -> Banque A - Courant | T20: =IF($K20="","",IF($S20="",0,IF(ISNUMBER(SEARCH("apport-exterieur",IFERROR(INDEX('Paramètres'!$N:$N,MATCH($D20,'Paramètres'!$M:$M,0))&"",""))),0,IF(OR(IFERROR(INDEX('Paramètres'!$I:$I,MATCH($C20,'Paramètres'!$D:$D,0))&"","")="Les deux",IFERROR(INDEX('Paramètres'!$I:$I,MATCH($C20,'Paramètres'!$D:$D,0))&"","")=IF($P20=1,"Débit",$L20)),-IF($P20=1,-$K20,$K20),0)))) -> 0 | U20: =IF($K20="","",IF(ISNUMBER(SEARCH("sortie-epargne",IFERROR(INDEX('Paramètres'!$N:$N,MATCH($D20,'Paramètres'!$M:$M,0))&"",""))),$K20,0)) -> 0 | V20: =IF(AND($A20<>"",$O20=1,$L20="Débit",N($Q20)>0,$A20>=Visualisation!$B$1,$A20<Visualisation!$D$1),MAX($V$1:V19)+1,"")
A21: 45548 | B21: Titre restaurant | C21: Titres-restaurant | D21: cantine | E21: 11.17 | G21: Cantine | I21: Villebourg | K21: =IF($E21="","",ROUND($E21*IF(ISNA(MATCH($C21,'Paramètres'!$D:$D,0)),1,IF(INDEX('Paramètres'!$J:$J,MATCH($C21,'Paramètres'!$D:$D,0))="",1,INDEX('Paramètres'!$J:$J,MATCH($C21,'Paramètres'!$D:$D,0)))),2)) -> 11.17 | L21: =IF($D21="","",IF($F21<>"",$F21,IF(ISNA(MATCH($D21,'Paramètres'!$M:$M,0)),"⚠ Type inconnu",IFERROR(INDEX('Paramètres'!$P:$P,MATCH($D21,'Paramètres'!$M:$M,0))&"","")))) -> Débit | M21: =IF($D21="","",IF(ISNA(MATCH($D21,'Paramètres'!$M:$M,0)),"⚠ Type inconnu",IF($L21="Crédit","",IFERROR(INDEX('Paramètres'!$O:$O,MATCH($D21,'Paramètres'!$M:$M,0))&"","")))) -> Dépense Courante | N21: =IF($D21="","",IFERROR(INDEX('Paramètres'!$Q:$Q,MATCH($D21,'Paramètres'!$M:$M,0))&"","")) -> Alimentation | O21: =IF($A21="","",IF(OR($J21<>"x",$A21<=FinReleve),1,0)) -> 1 | P21: =IF($D21="","",IF(AND($L21="Crédit",OR(IFERROR(INDEX('Paramètres'!$O:$O,MATCH($D21,'Paramètres'!$M:$M,0))&"","")<>"",ISNUMBER(SEARCH("remboursement",IFERROR(INDEX('Paramètres'!$N:$N,MATCH($D21,'Paramètres'!$M:$M,0))&"",""))))),1,0)) -> 0 | Q21: =IF($K21="","",IF(ISNUMBER(SEARCH("transfert-interne",IFERROR(INDEX('Paramètres'!$N:$N,MATCH($D21,'Paramètres'!$M:$M,0))&"",""))),0,IF($L21="Débit",$K21,IF($P21=1,-$K21,0)))) -> 11.17 | R21: =IF($K21="","",IF($L21="Crédit",$K21,-$K21)) -> -11.17 | S21: =IF($C21="","",IFERROR(INDEX('Paramètres'!$H:$H,MATCH($C21,'Paramètres'!$D:$D,0))&"","")) | T21: =IF($K21="","",IF($S21="",0,IF(ISNUMBER(SEARCH("apport-exterieur",IFERROR(INDEX('Paramètres'!$N:$N,MATCH($D21,'Paramètres'!$M:$M,0))&"",""))),0,IF(OR(IFERROR(INDEX('Paramètres'!$I:$I,MATCH($C21,'Paramètres'!$D:$D,0))&"","")="Les deux",IFERROR(INDEX('Paramètres'!$I:$I,MATCH($C21,'Paramètres'!$D:$D,0))&"","")=IF($P21=1,"Débit",$L21)),-IF($P21=1,-$K21,$K21),0)))) -> 0 | U21: =IF($K21="","",IF(ISNUMBER(SEARCH("sortie-epargne",IFERROR(INDEX('Paramètres'!$N:$N,MATCH($D21,'Paramètres'!$M:$M,0))&"",""))),$K21,0)) -> 0 | V21: =IF(AND($A21<>"",$O21=1,$L21="Débit",N($Q21)>0,$A21>=Visualisation!$B$1,$A21<Visualisation!$D$1),MAX($V$1:V20)+1,"")
A22: 45549 | B22: Titre restaurant | C22: Titres-restaurant | D22: cantine | E22: 9.43 | G22: Cantine | I22: Villebourg-sur-Rive | K22: =IF($E22="","",ROUND($E22*IF(ISNA(MATCH($C22,'Paramètres'!$D:$D,0)),1,IF(INDEX('Paramètres'!$J:$J,MATCH($C22,'Paramètres'!$D:$D,0))="",1,INDEX('Paramètres'!$J:$J,MATCH($C22,'Paramètres'!$D:$D,0)))),2)) -> 9.43 | L22: =IF($D22="","",IF($F22<>"",$F22,IF(ISNA(MATCH($D22,'Paramètres'!$M:$M,0)),"⚠ Type inconnu",IFERROR(INDEX('Paramètres'!$P:$P,MATCH($D22,'Paramètres'!$M:$M,0))&"","")))) -> Débit | M22: =IF($D22="","",IF(ISNA(MATCH($D22,'Paramètres'!$M:$M,0)),"⚠ Type inconnu",IF($L22="Crédit","",IFERROR(INDEX('Paramètres'!$O:$O,MATCH($D22,'Paramètres'!$M:$M,0))&"","")))) -> Dépense Courante | N22: =IF($D22="","",IFERROR(INDEX('Paramètres'!$Q:$Q,MATCH($D22,'Paramètres'!$M:$M,0))&"","")) -> Alimentation | O22: =IF($A22="","",IF(OR($J22<>"x",$A22<=FinReleve),1,0)) -> 1 | P22: =IF($D22="","",IF(AND($L22="Crédit",OR(IFERROR(INDEX('Paramètres'!$O:$O,MATCH($D22,'Paramètres'!$M:$M,0))&"","")<>"",ISNUMBER(SEARCH("remboursement",IFERROR(INDEX('Paramètres'!$N:$N,MATCH($D22,'Paramètres'!$M:$M,0))&"",""))))),1,0)) -> 0 | Q22: =IF($K22="","",IF(ISNUMBER(SEARCH("transfert-interne",IFERROR(INDEX('Paramètres'!$N:$N,MATCH($D22,'Paramètres'!$M:$M,0))&"",""))),0,IF($L22="Débit",$K22,IF($P22=1,-$K22,0)))) -> 9.43 | R22: =IF($K22="","",IF($L22="Crédit",$K22,-$K22)) -> -9.43 | S22: =IF($C22="","",IFERROR(INDEX('Paramètres'!$H:$H,MATCH($C22,'Paramètres'!$D:$D,0))&"","")) | T22: =IF($K22="","",IF($S22="",0,IF(ISNUMBER(SEARCH("apport-exterieur",IFERROR(INDEX('Paramètres'!$N:$N,MATCH($D22,'Paramètres'!$M:$M,0))&"",""))),0,IF(OR(IFERROR(INDEX('Paramètres'!$I:$I,MATCH($C22,'Paramètres'!$D:$D,0))&"","")="Les deux",IFERROR(INDEX('Paramètres'!$I:$I,MATCH($C22,'Paramètres'!$D:$D,0))&"","")=IF($P22=1,"Débit",$L22)),-IF($P22=1,-$K22,$K22),0)))) -> 0 | U22: =IF($K22="","",IF(ISNUMBER(SEARCH("sortie-epargne",IFERROR(INDEX('Paramètres'!$N:$N,MATCH($D22,'Paramètres'!$M:$M,0))&"",""))),$K22,0)) -> 0 | V22: =IF(AND($A22<>"",$O22=1,$L22="Débit",N($Q22)>0,$A22>=Visualisation!$B$1,$A22<Visualisation!$D$1),MAX($V$1:V21)+1,"")
A23: 45549 | B23: Loisirs | C23: Banque A - Part commune | D23: Loisirs | E23: 49.84 | G23: Concert | H23: Rentrée | I23: Villebourg-sur-Rive | K23: =IF($E23="","",ROUND($E23*IF(ISNA(MATCH($C23,'Paramètres'!$D:$D,0)),1,IF(INDEX('Paramètres'!$J:$J,MATCH($C23,'Paramètres'!$D:$D,0))="",1,INDEX('Paramètres'!$J:$J,MATCH($C23,'Paramètres'!$D:$D,0)))),2)) -> 24.92 | L23: =IF($D23="","",IF($F23<>"",$F23,IF(ISNA(MATCH($D23,'Paramètres'!$M:$M,0)),"⚠ Type inconnu",IFERROR(INDEX('Paramètres'!$P:$P,MATCH($D23,'Paramètres'!$M:$M,0))&"","")))) -> Débit | M23: =IF($D23="","",IF(ISNA(MATCH($D23,'Paramètres'!$M:$M,0)),"⚠ Type inconnu",IF($L23="Crédit","",IFERROR(INDEX('Paramètres'!$O:$O,MATCH($D23,'Paramètres'!$M:$M,0))&"","")))) -> Dépense Occasionnelle | N23: =IF($D23="","",IFERROR(INDEX('Paramètres'!$Q:$Q,MATCH($D23,'Paramètres'!$M:$M,0))&"","")) -> Loisir | O23: =IF($A23="","",IF(OR($J23<>"x",$A23<=FinReleve),1,0)) -> 1 | P23: =IF($D23="","",IF(AND($L23="Crédit",OR(IFERROR(INDEX('Paramètres'!$O:$O,MATCH($D23,'Paramètres'!$M:$M,0))&"","")<>"",ISNUMBER(SEARCH("remboursement",IFERROR(INDEX('Paramètres'!$N:$N,MATCH($D23,'Paramètres'!$M:$M,0))&"",""))))),1,0)) -> 0 | Q23: =IF($K23="","",IF(ISNUMBER(SEARCH("transfert-interne",IFERROR(INDEX('Paramètres'!$N:$N,MATCH($D23,'Paramètres'!$M:$M,0))&"",""))),0,IF($L23="Débit",$K23,IF($P23=1,-$K23,0)))) -> 24.92 | R23: =IF($K23="","",IF($L23="Crédit",$K23,-$K23)) -> -24.92 | S23: =IF($C23="","",IFERROR(INDEX('Paramètres'!$H:$H,MATCH($C23,'Paramètres'!$D:$D,0))&"","")) -> Banque A - Courant | T23: =IF($K23="","",IF($S23="",0,IF(ISNUMBER(SEARCH("apport-exterieur",IFERROR(INDEX('Paramètres'!$N:$N,MATCH($D23,'Paramètres'!$M:$M,0))&"",""))),0,IF(OR(IFERROR(INDEX('Paramètres'!$I:$I,MATCH($C23,'Paramètres'!$D:$D,0))&"","")="Les deux",IFERROR(INDEX('Paramètres'!$I:$I,MATCH($C23,'Paramètres'!$D:$D,0))&"","")=IF($P23=1,"Débit",$L23)),-IF($P23=1,-$K23,$K23),0)))) -> -24.92 | U23: =IF($K23="","",IF(ISNUMBER(SEARCH("sortie-epargne",IFERROR(INDEX('Paramètres'!$N:$N,MATCH($D23,'Paramètres'!$M:$M,0))&"",""))),$K23,0)) -> 0 | V23: =IF(AND($A23<>"",$O23=1,$L23="Débit",N($Q23)>0,$A23>=Visualisation!$B$1,$A23<Visualisation!$D$1),MAX($V$1:V22)+1,"")
A24: 45550 | B24: Electricité | C24: Banque C - Compte joint | D24: Electricité | E24: 86.34 | K24: =IF($E24="","",ROUND($E24*IF(ISNA(MATCH($C24,'Paramètres'!$D:$D,0)),1,IF(INDEX('Paramètres'!$J:$J,MATCH($C24,'Paramètres'!$D:$D,0))="",1,INDEX('Paramètres'!$J:$J,MATCH($C24,'Paramètres'!$D:$D,0)))),2)) -> 86.34 | L24: =IF($D24="","",IF($F24<>"",$F24,IF(ISNA(MATCH($D24,'Paramètres'!$M:$M,0)),"⚠ Type inconnu",IFERROR(INDEX('Paramètres'!$P:$P,MATCH($D24,'Paramètres'!$M:$M,0))&"","")))) -> Débit | M24: =IF($D24="","",IF(ISNA(MATCH($D24,'Paramètres'!$M:$M,0)),"⚠ Type inconnu",IF($L24="Crédit","",IFERROR(INDEX('Paramètres'!$O:$O,MATCH($D24,'Paramètres'!$M:$M,0))&"","")))) -> Dépense Fixe | N24: =IF($D24="","",IFERROR(INDEX('Paramètres'!$Q:$Q,MATCH($D24,'Paramètres'!$M:$M,0))&"","")) -> Immobilier | O24: =IF($A24="","",IF(OR($J24<>"x",$A24<=FinReleve),1,0)) -> 1 | P24: =IF($D24="","",IF(AND($L24="Crédit",OR(IFERROR(INDEX('Paramètres'!$O:$O,MATCH($D24,'Paramètres'!$M:$M,0))&"","")<>"",ISNUMBER(SEARCH("remboursement",IFERROR(INDEX('Paramètres'!$N:$N,MATCH($D24,'Paramètres'!$M:$M,0))&"",""))))),1,0)) -> 0 | Q24: =IF($K24="","",IF(ISNUMBER(SEARCH("transfert-interne",IFERROR(INDEX('Paramètres'!$N:$N,MATCH($D24,'Paramètres'!$M:$M,0))&"",""))),0,IF($L24="Débit",$K24,IF($P24=1,-$K24,0)))) -> 86.34 | R24: =IF($K24="","",IF($L24="Crédit",$K24,-$K24)) -> -86.34 | S24: =IF($C24="","",IFERROR(INDEX('Paramètres'!$H:$H,MATCH($C24,'Paramètres'!$D:$D,0))&"","")) -> Banque A - Courant | T24: =IF($K24="","",IF($S24="",0,IF(ISNUMBER(SEARCH("apport-exterieur",IFERROR(INDEX('Paramètres'!$N:$N,MATCH($D24,'Paramètres'!$M:$M,0))&"",""))),0,IF(OR(IFERROR(INDEX('Paramètres'!$I:$I,MATCH($C24,'Paramètres'!$D:$D,0))&"","")="Les deux",IFERROR(INDEX('Paramètres'!$I:$I,MATCH($C24,'Paramètres'!$D:$D,0))&"","")=IF($P24=1,"Débit",$L24)),-IF($P24=1,-$K24,$K24),0)))) -> 0 | U24: =IF($K24="","",IF(ISNUMBER(SEARCH("sortie-epargne",IFERROR(INDEX('Paramètres'!$N:$N,MATCH($D24,'Paramètres'!$M:$M,0))&"",""))),$K24,0)) -> 0 | V24: =IF(AND($A24<>"",$O24=1,$L24="Débit",N($Q24)>0,$A24>=Visualisation!$B$1,$A24<Visualisation!$D$1),MAX($V$1:V23)+1,"")
A25: 45550 | B25: Remboursement | C25: Banque B - Compte joint | D25: Virement extérieur | E25: 386.04 | K25: =IF($E25="","",ROUND($E25*IF(ISNA(MATCH($C25,'Paramètres'!$D:$D,0)),1,IF(INDEX('Paramètres'!$J:$J,MATCH($C25,'Paramètres'!$D:$D,0))="",1,INDEX('Paramètres'!$J:$J,MATCH($C25,'Paramètres'!$D:$D,0)))),2)) -> 193.02 | L25: =IF($D25="","",IF($F25<>"",$F25,IF(ISNA(MATCH($D25,'Paramètres'!$M:$M,0)),"⚠ Type inconnu",IFERROR(INDEX('Paramètres'!$P:$P,MATCH($D25,'Paramètres'!$M:$M,0))&"","")))) -> Crédit | M25: =IF($D25="","",IF(ISNA(MATCH($D25,'Paramètres'!$M:$M,0)),"⚠ Type inconnu",IF($L25="Crédit","",IFERROR(INDEX('Paramètres'!$O:$O,MATCH($D25,'Paramètres'!$M:$M,0))&"","")))) | N25: =IF($D25="","",IFERROR(INDEX('Paramètres'!$Q:$Q,MATCH($D25,'Paramètres'!$M:$M,0))&"","")) -> Comptes Bancaires | O25: =IF($A25="","",IF(OR($J25<>"x",$A25<=FinReleve),1,0)) -> 1 | P25: =IF($D25="","",IF(AND($L25="Crédit",OR(IFERROR(INDEX('Paramètres'!$O:$O,MATCH($D25,'Paramètres'!$M:$M,0))&"","")<>"",ISNUMBER(SEARCH("remboursement",IFERROR(INDEX('Paramètres'!$N:$N,MATCH($D25,'Paramètres'!$M:$M,0))&"",""))))),1,0)) -> 0 | Q25: =IF($K25="","",IF(ISNUMBER(SEARCH("transfert-interne",IFERROR(INDEX('Paramètres'!$N:$N,MATCH($D25,'Paramètres'!$M:$M,0))&"",""))),0,IF($L25="Débit",$K25,IF($P25=1,-$K25,0)))) -> 0 | R25: =IF($K25="","",IF($L25="Crédit",$K25,-$K25)) -> 193.02 | S25: =IF($C25="","",IFERROR(INDEX('Paramètres'!$H:$H,MATCH($C25,'Paramètres'!$D:$D,0))&"","")) -> Banque A - Courant | T25: =IF($K25="","",IF($S25="",0,IF(ISNUMBER(SEARCH("apport-exterieur",IFERROR(INDEX('Paramètres'!$N:$N,MATCH($D25,'Paramètres'!$M:$M,0))&"",""))),0,IF(OR(IFERROR(INDEX('Paramètres'!$I:$I,MATCH($C25,'Paramètres'!$D:$D,0))&"","")="Les deux",IFERROR(INDEX('Paramètres'!$I:$I,MATCH($C25,'Paramètres'!$D:$D,0))&"","")=IF($P25=1,"Débit",$L25)),-IF($P25=1,-$K25,$K25),0)))) -> 0 | U25: =IF($K25="","",IF(ISNUMBER(SEARCH("sortie-epargne",IFERROR(INDEX('Paramètres'!$N:$N,MATCH($D25,'Paramètres'!$M:$M,0))&"",""))),$K25,0)) -> 0 | V25: =IF(AND($A25<>"",$O25=1,$L25="Débit",N($Q25)>0,$A25>=Visualisation!$B$1,$A25<Visualisation!$D$1),MAX($V$1:V24)+1,"")
A26: 45551 | B26: Achat carte | C26: Banque B - Compte joint | D26: courses | E26: 100.4 | G26: Boulangerie | I26: Villebourg-sur-Rive | K26: =IF($E26="","",ROUND($E26*IF(ISNA(MATCH($C26,'Paramètres'!$D:$D,0)),1,IF(INDEX('Paramètres'!$J:$J,MATCH($C26,'Paramètres'!$D:$D,0))="",1,INDEX('Paramètres'!$J:$J,MATCH($C26,'Paramètres'!$D:$D,0)))),2)) -> 50.2 | L26: =IF($D26="","",IF($F26<>"",$F26,IF(ISNA(MATCH($D26,'Paramètres'!$M:$M,0)),"⚠ Type inconnu",IFERROR(INDEX('Paramètres'!$P:$P,MATCH($D26,'Paramètres'!$M:$M,0))&"","")))) -> Débit | M26: =IF($D26="","",IF(ISNA(MATCH($D26,'Paramètres'!$M:$M,0)),"⚠ Type inconnu",IF($L26="Crédit","",IFERROR(INDEX('Paramètres'!$O:$O,MATCH($D26,'Paramètres'!$M:$M,0))&"","")))) -> Dépense Courante | N26: =IF($D26="","",IFERROR(INDEX('Paramètres'!$Q:$Q,MATCH($D26,'Paramètres'!$M:$M,0))&"","")) -> Alimentation | O26: =IF($A26="","",IF(OR($J26<>"x",$A26<=FinReleve),1,0)) -> 1 | P26: =IF($D26="","",IF(AND($L26="Crédit",OR(IFERROR(INDEX('Paramètres'!$O:$O,MATCH($D26,'Paramètres'!$M:$M,0))&"","")<>"",ISNUMBER(SEARCH("remboursement",IFERROR(INDEX('Paramètres'!$N:$N,MATCH($D26,'Paramètres'!$M:$M,0))&"",""))))),1,0)) -> 0 | Q26: =IF($K26="","",IF(ISNUMBER(SEARCH("transfert-interne",IFERROR(INDEX('Paramètres'!$N:$N,MATCH($D26,'Paramètres'!$M:$M,0))&"",""))),0,IF($L26="Débit",$K26,IF($P26=1,-$K26,0)))) -> 50.2 | R26: =IF($K26="","",IF($L26="Crédit",$K26,-$K26)) -> -50.2 | S26: =IF($C26="","",IFERROR(INDEX('Paramètres'!$H:$H,MATCH($C26,'Paramètres'!$D:$D,0))&"","")) -> Banque A - Courant | T26: =IF($K26="","",IF($S26="",0,IF(ISNUMBER(SEARCH("apport-exterieur",IFERROR(INDEX('Paramètres'!$N:$N,MATCH($D26,'Paramètres'!$M:$M,0))&"",""))),0,IF(OR(IFERROR(INDEX('Paramètres'!$I:$I,MATCH($C26,'Paramètres'!$D:$D,0))&"","")="Les deux",IFERROR(INDEX('Paramètres'!$I:$I,MATCH($C26,'Paramètres'!$D:$D,0))&"","")=IF($P26=1,"Débit",$L26)),-IF($P26=1,-$K26,$K26),0)))) -> 0 | U26: =IF($K26="","",IF(ISNUMBER(SEARCH("sortie-epargne",IFERROR(INDEX('Paramètres'!$N:$N,MATCH($D26,'Paramètres'!$M:$M,0))&"",""))),$K26,0)) -> 0 | V26: =IF(AND($A26<>"",$O26=1,$L26="Débit",N($Q26)>0,$A26>=Visualisation!$B$1,$A26<Visualisation!$D$1),MAX($V$1:V25)+1,"")
A27: 45552 | B27: Titre restaurant | C27: Titres-restaurant | D27: cantine | E27: 7.96 | G27: Cantine | I27: Villebourg-sur-Rive | K27: =IF($E27="","",ROUND($E27*IF(ISNA(MATCH($C27,'Paramètres'!$D:$D,0)),1,IF(INDEX('Paramètres'!$J:$J,MATCH($C27,'Paramètres'!$D:$D,0))="",1,INDEX('Paramètres'!$J:$J,MATCH($C27,'Paramètres'!$D:$D,0)))),2)) -> 7.96 | L27: =IF($D27="","",IF($F27<>"",$F27,IF(ISNA(MATCH($D27,'Paramètres'!$M:$M,0)),"⚠ Type inconnu",IFERROR(INDEX('Paramètres'!$P:$P,MATCH($D27,'Paramètres'!$M:$M,0))&"","")))) -> Débit | M27: =IF($D27="","",IF(ISNA(MATCH($D27,'Paramètres'!$M:$M,0)),"⚠ Type inconnu",IF($L27="Crédit","",IFERROR(INDEX('Paramètres'!$O:$O,MATCH($D27,'Paramètres'!$M:$M,0))&"","")))) -> Dépense Courante | N27: =IF($D27="","",IFERROR(INDEX('Paramètres'!$Q:$Q,MATCH($D27,'Paramètres'!$M:$M,0))&"","")) -> Alimentation | O27: =IF($A27="","",IF(OR($J27<>"x",$A27<=FinReleve),1,0)) -> 1 | P27: =IF($D27="","",IF(AND($L27="Crédit",OR(IFERROR(INDEX('Paramètres'!$O:$O,MATCH($D27,'Paramètres'!$M:$M,0))&"","")<>"",ISNUMBER(SEARCH("remboursement",IFERROR(INDEX('Paramètres'!$N:$N,MATCH($D27,'Paramètres'!$M:$M,0))&"",""))))),1,0)) -> 0 | Q27: =IF($K27="","",IF(ISNUMBER(SEARCH("transfert-interne",IFERROR(INDEX('Paramètres'!$N:$N,MATCH($D27,'Paramètres'!$M:$M,0))&"",""))),0,IF($L27="Débit",$K27,IF($P27=1,-$K27,0)))) -> 7.96 | R27: =IF($K27="","",IF($L27="Crédit",$K27,-$K27)) -> -7.96 | S27: =IF($C27="","",IFERROR(INDEX('Paramètres'!$H:$H,MATCH($C27,'Paramètres'!$D:$D,0))&"","")) | T27: =IF($K27="","",IF($S27="",0,IF(ISNUMBER(SEARCH("apport-exterieur",IFERROR(INDEX('Paramètres'!$N:$N,MATCH($D27,'Paramètres'!$M:$M,0))&"",""))),0,IF(OR(IFERROR(INDEX('Paramètres'!$I:$I,MATCH($C27,'Paramètres'!$D:$D,0))&"","")="Les deux",IFERROR(INDEX('Paramètres'!$I:$I,MATCH($C27,'Paramètres'!$D:$D,0))&"","")=IF($P27=1,"Débit",$L27)),-IF($P27=1,-$K27,$K27),0)))) -> 0 | U27: =IF($K27="","",IF(ISNUMBER(SEARCH("sortie-epargne",IFERROR(INDEX('Paramètres'!$N:$N,MATCH($D27,'Paramètres'!$M:$M,0))&"",""))),$K27,0)) -> 0 | V27: =IF(AND($A27<>"",$O27=1,$L27="Débit",N($Q27)>0,$A27>=Visualisation!$B$1,$A27<Visualisation!$D$1),MAX($V$1:V26)+1,"")
A28: 45553 | B28: Impôt sur Revenu | C28: Banque A - Courant | D28: Impôt sur Revenu | E28: 212 | K28: =IF($E28="","",ROUND($E28*IF(ISNA(MATCH($C28,'Paramètres'!$D:$D,0)),1,IF(INDEX('Paramètres'!$J:$J,MATCH($C28,'Paramètres'!$D:$D,0))="",1,INDEX('Paramètres'!$J:$J,MATCH($C28,'Paramètres'!$D:$D,0)))),2)) -> 212 | L28: =IF($D28="","",IF($F28<>"",$F28,IF(ISNA(MATCH($D28,'Paramètres'!$M:$M,0)),"⚠ Type inconnu",IFERROR(INDEX('Paramètres'!$P:$P,MATCH($D28,'Paramètres'!$M:$M,0))&"","")))) -> Débit | M28: =IF($D28="","",IF(ISNA(MATCH($D28,'Paramètres'!$M:$M,0)),"⚠ Type inconnu",IF($L28="Crédit","",IFERROR(INDEX('Paramètres'!$O:$O,MATCH($D28,'Paramètres'!$M:$M,0))&"","")))) -> Dépense Fixe | N28: =IF($D28="","",IFERROR(INDEX('Paramètres'!$Q:$Q,MATCH($D28,'Paramètres'!$M:$M,0))&"","")) -> Impots | O28: =IF($A28="","",IF(OR($J28<>"x",$A28<=FinReleve),1,0)) -> 1 | P28: =IF($D28="","",IF(AND($L28="Crédit",OR(IFERROR(INDEX('Paramètres'!$O:$O,MATCH($D28,'Paramètres'!$M:$M,0))&"","")<>"",ISNUMBER(SEARCH("remboursement",IFERROR(INDEX('Paramètres'!$N:$N,MATCH($D28,'Paramètres'!$M:$M,0))&"",""))))),1,0)) -> 0 | Q28: =IF($K28="","",IF(ISNUMBER(SEARCH("transfert-interne",IFERROR(INDEX('Paramètres'!$N:$N,MATCH($D28,'Paramètres'!$M:$M,0))&"",""))),0,IF($L28="Débit",$K28,IF($P28=1,-$K28,0)))) -> 212 | R28: =IF($K28="","",IF($L28="Crédit",$K28,-$K28)) -> -212 | S28: =IF($C28="","",IFERROR(INDEX('Paramètres'!$H:$H,MATCH($C28,'Paramètres'!$D:$D,0))&"","")) | T28: =IF($K28="","",IF($S28="",0,IF(ISNUMBER(SEARCH("apport-exterieur",IFERROR(INDEX('Paramètres'!$N:$N,MATCH($D28,'Paramètres'!$M:$M,0))&"",""))),0,IF(OR(IFERROR(INDEX('Paramètres'!$I:$I,MATCH($C28,'Paramètres'!$D:$D,0))&"","")="Les deux",IFERROR(INDEX('Paramètres'!$I:$I,MATCH($C28,'Paramètres'!$D:$D,0))&"","")=IF($P28=1,"Débit",$L28)),-IF($P28=1,-$K28,$K28),0)))) -> 0 | U28: =IF($K28="","",IF(ISNUMBER(SEARCH("sortie-epargne",IFERROR(INDEX('Paramètres'!$N:$N,MATCH($D28,'Paramètres'!$M:$M,0))&"",""))),$K28,0)) -> 0 | V28: =IF(AND($A28<>"",$O28=1,$L28="Débit",N($Q28)>0,$A28>=Visualisation!$B$1,$A28<Visualisation!$D$1),MAX($V$1:V27)+1,"")
